<?xml version="1.0"?>

<robot name="robot" xmlns:xacro="http://www.ros.org/wiki/xacro">


	<xacro:property name="length_wheel" value="0.0197" />
	<xacro:property name="radius_wheel" value="0.075" />
	<xacro:property name="camera_link" value="0.05" /> 
        <xacro:property name="PI" value="3.1415926"/>
	<xacro:macro name="default_inertial" params="mass">
               <inertial>
                       <mass value="${mass}" />
                       <inertia ixx="0.01" ixy="0.0" 
                                ixz="0.0"
                                iyy="0.01" iyz="0.0"
                                izz="0.01" />
               </inertial>
	</xacro:macro>
    <!-- <link name="dummy">
    </link> -->
  <link name="base_footprint"/>

	<gazebo reference="base_footprint">
		<material>Gazebo/Green</material>
		<turnGravityOff>false</turnGravityOff>
	</gazebo>

	<joint name="base_footprint_joint" type="fixed">
		<origin xyz="0 0 0" />
		<parent link="base_footprint" />
		<child link="base_link" />
	</joint>


	<link name="base_link">
   		<visual>
			<geometry>
      				<box size="0.425 0.38 .1"/>
     			</geometry>
			<origin rpy="0 0 ${PI/2}" xyz="0 0 0.05"/>  
			<material name="white">
				<color rgba="1 1 1 1"/>
			</material>
   		</visual>
		<collision>
			<geometry>
       				<box size="0.425 0.38 0.1"/>
			</geometry>
		</collision>
                <xacro:default_inertial mass="8.2"/>    
 	</link>

 	<link name="wheel_1">
   		<visual>
     			<geometry>
       				<cylinder length="${length_wheel}" radius="${radius_wheel}"/>
     			</geometry>
			<!-- <origin rpy="0 1.5 0" xyz="0.1 0.1 0"/> -->
			<origin rpy="0 0 0" xyz="0 0 0"/>
   			<material name="black">
				<color rgba="0 0 0 1"/>
			</material>
		</visual>
		<collision>
			<geometry>
       				<cylinder length="${length_wheel}" radius="${radius_wheel}"/>
			</geometry>
		</collision>
		  <mu1>0.5</mu1>
		    <mu2>0.5</mu2>
		    <!-- <mu1>0.5</mu1>
		    <mu2>0.5</mu2> -->
		<xacro:default_inertial mass="0.5"/>  
 	</link>

 

 	<link name="wheel_2">
   		<visual>
     			<geometry>
       				<cylinder length="${length_wheel}" radius="${radius_wheel}"/>
     			</geometry>
			<!-- <origin rpy="0 1.5 0" xyz="-0.1 0.1 0"/> -->
			<origin rpy="0 0 0" xyz="0 0 0"/>
   			<material name="black"/>
   		</visual>
		<collision>
			<geometry>
       				<cylinder length="${length_wheel}" radius="${radius_wheel}"/>
			</geometry>
		</collision>
		   <mu1>0.5</mu1>
		    <mu2>0.5</mu2>
		    <!-- <mu1>0.5</mu1>
		    <mu2>0.5</mu2> -->
		<xacro:default_inertial mass="0.5"/>  

 	</link>
    
 	<link name="wheel_3">
   		<visual>
     			<geometry>
       				<cylinder length="${length_wheel}" radius="${radius_wheel}"/>
     			</geometry>
			<!-- <origin rpy="0 1.5 0" xyz="0.1 -0.1 0"/> -->

			<origin rpy="0 0 0" xyz="0 0 0"/>
   			<material name="black"/>
   		</visual>
		<collision>
			<geometry>
       				<cylinder length="${length_wheel}" radius="${radius_wheel}"/>
			</geometry>
		</collision>
		 <mu1>0.5</mu1>
		    <mu2>0.5</mu2>
		    <!-- <mu1>0.5</mu1>
		    <mu2>0.5</mu2> -->
		<xacro:default_inertial mass="0.5"/>    
 	</link>

 	<link name="wheel_4">
   		<visual>
     			<geometry>
       				<cylinder length="${length_wheel}" radius="${radius_wheel}"/>
     			</geometry>
		<!--	<origin rpy="0 1.5 0" xyz="-0.1 -0.1 0"/> -->
			<origin rpy="0 0 0" xyz="0 0 0" />
   			<material name="black"/>
   		</visual>
		<collision>
			<geometry>
       				<cylinder length="${length_wheel}" radius="${radius_wheel}"/>
			</geometry>
		</collision>
		   <mu1>0.5</mu1>
		    <mu2>0.5</mu2>
		    <!-- <mu1>0.5</mu1>
		    <mu2>0.5</mu2> -->
		<xacro:default_inertial mass="0.5"/>    

 	</link>



 <joint name="base_to_wheel1" type="continuous">
   <parent link="base_link"/>
   <child link="wheel_1"/>
   <origin rpy="${-PI/2} 0 0" xyz="0.14 0.2298 -0.01"/>
   <axis xyz="0 0 1" />
 </joint>

 <joint name="base_to_wheel2" type="continuous">
   <axis xyz="0 0 1" />
   <anchor xyz="0 0 0" />
   <limit effort="100" velocity="100" />
   <parent link="base_link"/>
   <child link="wheel_2"/>
   <origin rpy="${-PI/2} 0 0" xyz="-0.14 0.2298 -0.01"/>
</joint>

 <joint name="base_to_wheel3" type="continuous">
   <parent link="base_link"/>
   <axis xyz="0 0 1" />
   <child link="wheel_3"/>
   <origin rpy="${-PI/2} 0 0" xyz="0.14 -0.2298 -0.01"/>
 </joint>

 <joint name="base_to_wheel4" type="continuous">
   <parent link="base_link"/>
   <axis xyz="0 0 1" />
   <child link="wheel_4"/>
   <origin rpy="${-PI/2} 0 0" xyz="-0.14 -0.2298 -0.01"/>
 </joint>

 <!-- IMU joint -->
  <joint name="imu_joint" type="fixed">
    <axis xyz="0 1 0" />
    <origin xyz="0.092 0 -0.035" rpy="0 0 3.14159"/>
    <parent link="base_link"/>
    <child link="imu_link"/>
  </joint>

  <!-- IMU -->
  <link name="imu_link">
    <collision>
      <origin xyz="0 0 0" rpy="0 0 0"/>
        <geometry>
          <box size="0.005 0.005 0.005"/>
        </geometry>
    </collision>

    <visual>
      <origin xyz="0 0 0" rpy="0 0 0"/>
        <geometry>
          <box size="0.005 0.005 0.005"/>
        </geometry>
      <material name="green">
  <color rgba="0 1 0 1"/>
      </material>
    </visual>

    <inertial>
      <mass value="1e-2" />
      <origin xyz="0 0 0" rpy="0 0 0"/>
      <inertia ixx="1e-6" ixy="0" ixz="0" iyy="1e-6" iyz="0" izz="1e-6" />
    </inertial>
  </link>


     <!-- IMU -->

  <!-- Camera joint -->
  <!-- <joint name="camera_joint" type="fixed">
    <axis xyz="0 1 0" />
    <origin xyz="0.125 0 0.175" rpy="0 0 0"/>
    <parent link="base_link"/>
    <child link="camera_link"/>
  </joint> -->

  <!-- Camera -->
  <!-- <link name="camera_link">
    <collision>
      <origin xyz="0 0 0" rpy="0 0 0"/>
      <geometry>
	<box size="0.05 0.05 0.05"/>
      </geometry>
    </collision>

    <visual>
      <origin xyz="0 0 0" rpy="0 0 0"/>
      <geometry>
	<box size="0.05 0.05 0.05"/>
      </geometry>
      <material name="red">
	<color rgba="1 0 0 1"/>
      </material>
    </visual>

    <inertial>
      <mass value="1e-2" />
      <origin xyz="0 0 0" rpy="0 0 0"/>
      <inertia ixx="1e-6" ixy="0" ixz="0" iyy="1e-6" iyz="0" izz="1e-6" />
    </inertial>
  </link> -->


     <!-- camera -->



  <!-- laser joint -->
  <joint name="laser_joint" type="fixed">
    <origin xyz="0.0 0.0 -0.0051" rpy="3.141592 0 3.141592"/>
    <parent link="base_link"/>
    <axis xyz="0 1 0" />
    <child link="laser_frame"/>
  </joint>

  <!-- laser Laser -->
  <link name="laser_frame">
    <collision>
      <origin xyz="0 0 0" rpy="0 0 0"/>
      <geometry>
        <cylinder radius="0.02" length="0.02"/>
      </geometry>
    </collision>

    <visual>
      <origin xyz="0 0 0" rpy="0 0 0"/>
      <geometry>
        <cylinder radius="0.02" length="0.02"/>
      </geometry>
    </visual>

    <inertial>
      <mass value="1e-2" />
      <origin xyz="0 0 0" rpy="0 0 0"/>
      <inertia ixx="1e-6" ixy="0" ixz="0" iyy="1e-6" iyz="0" izz="1e-6" />
    </inertial>
  </link>


   <!-- hokuyo -->

<!-- gazebo插件设置相关 -->

   <gazebo reference="base_link">
    <material>Gazebo/Orange</material>
  </gazebo>

 <gazebo reference="wheel_1">
        <material>Gazebo/Red</material>
 </gazebo>

 <gazebo reference="wheel_2">
        <material>Gazebo/Black</material>
 </gazebo>

 <gazebo reference="wheel_3">
        <material>Gazebo/Red</material>
 </gazebo>

 <gazebo reference="wheel_4">
        <material>Gazebo/Black</material>
 </gazebo>


  <!-- ros_control plugin -->
<!--   <gazebo>
    <plugin name="gazebo_ros_control" filename="libgazebo_ros_control.so">
      <robotNamespace>/robot</robotNamespace>
       <legacyModeNS> true </legacyModeNS>   
    </plugin>
  </gazebo> -->

  

  <!-- camera_link -->
  <gazebo reference="camera_link">   
    <material>Gazebo/Red</material>
  </gazebo>

  <!-- hokuyo -->
  <gazebo reference="laser_frame">
    <sensor type="ray" name="head_hokuyo_sensor">
   <!-- <sensor type="gpu_ray" name="head_hokuyo_sensor">   -->
    <!-- GPU -->
      <pose>0 0 0 3.14159265 0 0</pose>
      <visualize>false</visualize>
      <update_rate>40</update_rate>
      <ray>
        <scan>
          <horizontal>
            <samples>720</samples>
            <resolution>1</resolution>
            <min_angle>-3.1415926</min_angle>
            <max_angle>3.1415926</max_angle>
          </horizontal>
        </scan>
        <range>
          <min>0.05</min>
          <max>30.0</max>
          <resolution>0.01</resolution>
        </range>
        <noise>
          <type>gaussian</type>
          <!-- Noise parameters based on published spec for Hokuyo laser
               achieving "+-30mm" accuracy at range < 10m.  A mean of 0.0m and
               stddev of 0.01m will put 99.7% of samples within 0.03m of the true
               reading. -->
          <mean>0.0</mean>
          <stddev>0.01</stddev>
        </noise>
      </ray>
      <!-- GPU版本 -->
      <!-- <plugin name="gazebo_ros_head_hokuyo_controller" filename="libgazebo_ros_gpu_laser.so">  -->
      <plugin name="gazebo_ros_head_hokuyo_controller" filename="libgazebo_ros_laser.so">
        <topicName>/scan</topicName>
        <frameName>laser_frame</frameName>
      </plugin>
    </sensor>
  </gazebo>

  <!-- camera -->
  <gazebo reference="camera_link">
    <sensor type="camera" name="camera1">
      <update_rate>30.0</update_rate>
      <camera name="head">
        <horizontal_fov>1.3962634</horizontal_fov>
        <image>
          <width>1920</width>
          <height>1080</height>
          <format>R8G8B8</format>
        </image>
        <clip>
          <near>0.02</near>
          <far>300</far>
        </clip>
        <noise>
          <type>gaussian</type>
          <!-- Noise is sampled independently per pixel on each frame.  
               That pixel's noise value is added to each of its color
               channels, which at that point lie in the range [0,1]. -->
          <mean>0.0</mean>
          <stddev>0.007</stddev>
        </noise>
      </camera>
      <plugin name="camera_controller" filename="libgazebo_ros_camera.so">
        <alwaysOn>true</alwaysOn>
        <updateRate>0.0</updateRate>
        <cameraName>/</cameraName>
        <imageTopicName>cam</imageTopicName>
        <cameraInfoTopicName>camera_info</cameraInfoTopicName>
        <frameName>camera_link</frameName>
        <hackBaseline>0.07</hackBaseline>
        <distortionK1>0.0</distortionK1>
        <distortionK2>0.0</distortionK2>
        <distortionK3>0.0</distortionK3>
        <distortionT1>0.0</distortionT1>
        <distortionT2>0.0</distortionT2>
      </plugin>
    </sensor>
  </gazebo>  

  <!-- Drive controller -->
<!-- <gazebo>
  <plugin name="skid_steer_drive_controller" filename="libgazebo_ros_skid_steer_drive.so">
    <alwaysOn>true</alwaysOn>
    <updateRate>100.0</updateRate>
    <robotNamespace>/</robotNamespace>
    <leftFrontJoint>base_to_wheel1</leftFrontJoint>
    <rightFrontJoint>base_to_wheel3</rightFrontJoint>
    <leftRearJoint>base_to_wheel2</leftRearJoint>
    <rightRearJoint>base_to_wheel4</rightRearJoint>
    <wheelSeparation>0.26</wheelSeparation>
    <wheelDiameter>0.12</wheelDiameter>
    <torque>2</torque>
    <commandTopic>cmd_vel</commandTopic>
    <odometryTopic>odom</odometryTopic>
    <odometryFrame>odom</odometryFrame>
    <robotBaseFrame>base_footprint</robotBaseFrame>
    <broadcastTF>1</broadcastTF>
  </plugin>
</gazebo> -->

  <!-- Drive controller -->
<gazebo>

<plugin name="mecanum_controller" filename="libgazebo_ros_planar_move.so">
 <alwaysOn>true</alwaysOn>
    <updateRate>100.0</updateRate>
    <robotNamespace>/</robotNamespace>
    <commandTopic>cmd_vel</commandTopic>
    <odometryTopic>odom</odometryTopic>
    <odometryFrame>odom</odometryFrame>
    <leftFrontJoint>base_to_wheel1</leftFrontJoint>
    <rightFrontJoint>base_to_wheel3</rightFrontJoint>
    <leftRearJoint>base_to_wheel2</leftRearJoint>
    <rightRearJoint>base_to_wheel4</rightRearJoint>
    <wheelSeparation>0.26</wheelSeparation>
    <wheelDiameter>0.12</wheelDiameter>
    <odometryRate>20.0</odometryRate>
    <torque>2</torque>
    <robotBaseFrame>base_footprint</robotBaseFrame>
    <publishOdomTF>true</publishOdomTF>
    <broadcastTF>true</broadcastTF>
</plugin>
</gazebo>
<!-- <gazebo>
  <plugin name="gazebo_ros_mecanum_diff_drive" filename="libgazebo_ros_mecanum_diff_drive.so">
    <commandTopic>cmd_vel</commandTopic>
    <odometryTopic>odom</odometryTopic>
    <odometryFrame>odom</odometryFrame>
    <robotBaseFrame>base_footprint</robotBaseFrame>
    <LeftRear>wheel_joint_1</LeftRear>
    <LeftFront>wheel_joint_2</LeftFront>
    <RightFront>wheel_joint_3</RightFront>
    <RightRear>wheel_joint_4</RightRear>
    <odometryRate>20</odometryRate>      
    <publishWheelTF>true</publishWheelTF>
    <publishWheelJointState>true</publishWheelJointState>
    <WheelTorque>1</WheelTorque>
    <WheelSeparationW>0.4596</WheelSeparationW>
    <WheelSeparationL>0.28</WheelSeparationL>
    <wheelAccel>5</wheelAccel>
    <wheelDiameter>0.13</wheelDiameter>
    <publishOdom>false</publishOdom>
    <isRollerModel>true</isRollerModel>
  </plugin>
</gazebo> -->

<!-- imu控制 -->

<gazebo reference="imu_link">
  <sensor name="imu_sensor" type="imu">
   <plugin filename="libgazebo_ros_imu_sensor.so" name="imu_plugin">
      <ros>
        <namespace>/</namespace>
        <remapping>~/out:=imu</remapping>
      </ros>
      <initial_orientation_as_reference>false</initial_orientation_as_reference>
    </plugin>
    <always_on>true</always_on>
    <update_rate>100</update_rate>
    <visualize>true</visualize>
    <imu>
      <angular_velocity>
        <x>
          <noise type="gaussian">
            <mean>0.0</mean>
            <stddev>2e-4</stddev>
            <bias_mean>0.0000075</bias_mean>
            <bias_stddev>0.0000008</bias_stddev>
          </noise>
        </x>
        <y>
          <noise type="gaussian">
            <mean>0.0</mean>
            <stddev>2e-4</stddev>
            <bias_mean>0.0000075</bias_mean>
            <bias_stddev>0.0000008</bias_stddev>
          </noise>
        </y>
        <z>
          <noise type="gaussian">
            <mean>0.0</mean>
            <stddev>2e-4</stddev>
            <bias_mean>0.0000075</bias_mean>
            <bias_stddev>0.0000008</bias_stddev>
          </noise>
        </z>
      </angular_velocity>
      <linear_acceleration>
        <x>
          <noise type="gaussian">
            <mean>0.0</mean>
            <stddev>1.7e-2</stddev>
            <bias_mean>0.1</bias_mean>
            <bias_stddev>0.001</bias_stddev>
          </noise>
        </x>
        <y>
          <noise type="gaussian">
            <mean>0.0</mean>
            <stddev>1.7e-2</stddev>
            <bias_mean>0.1</bias_mean>
            <bias_stddev>0.001</bias_stddev>
          </noise>
        </y>
        <z>
          <noise type="gaussian">
            <mean>0.0</mean>
            <stddev>1.7e-2</stddev>
            <bias_mean>0.1</bias_mean>
            <bias_stddev>0.001</bias_stddev>
          </noise>
        </z>
      </linear_acceleration>
      <orientation>
        <x>
          <noise type="gaussian">
            <mean>0.0</mean>
            <stddev>1.7e-2</stddev>
            <bias_mean>0.1</bias_mean>
            <bias_stddev>0.001</bias_stddev>
          </noise>
        </x>
        <y>
          <noise type="gaussian">
            <mean>0.0</mean>
            <stddev>1.7e-2</stddev>
            <bias_mean>0.1</bias_mean>
            <bias_stddev>0.001</bias_stddev>
          </noise>
        </y>
        <z>
          <noise type="gaussian">
            <mean>0.0</mean>
            <stddev>1.7e-2</stddev>
            <bias_mean>0.1</bias_mean>
            <bias_stddev>0.001</bias_stddev>
          </noise>
        </z>
        <w>
          <noise type="gaussian">
            <mean>0.0</mean>
            <stddev>1.7e-2</stddev>
            <bias_mean>0.1</bias_mean>
            <bias_stddev>0.001</bias_stddev>
          </noise>
        </w>
      </orientation>
    </imu>
  </sensor>
</gazebo>

<!-- gazebo插件设置相关结束 -->

</robot>